# openweathermap: test-before-configure

| Info   | Value                                                                    |
|--------|--------------------------------------------------------------------------|
| Name   | [openweathermap](https://www.home-assistant.io/integrations/openweathermap/) |
| Rule   | [test-before-configure](https://developers.home-assistant.io/docs/core/integration-quality-scale/rules/test-before-configure)                                                     |
| Status | **todo**                                                                 |
| Reason |                                                                          |

## Overview

The `test-before-configure` rule requires that integrations test any connection to a device or service during the config flow and report failures to the user before the configuration entry is created. This helps catch issues like incorrect credentials, network problems, or unsupported devices early on.

This rule applies to the `openweathermap` integration because:
1.  It has a `config_flow` (as indicated in `manifest.json`).
2.  It connects to an external cloud service (OpenWeatherMap API), which requires an API key and network connectivity.
3.  It does not fall under the exemptions (e.g., helpers or pure runtime auto-discovery integrations).

The `openweathermap` integration partially follows this rule but has a gap in robust error handling for unexpected issues during the validation step.

**Current Implementation:**
*   In `homeassistant/components/openweathermap/config_flow.py`, the `async_step_user` method calls `await validate_api_key(...)` to check the provided API key and connection.
    ```python
    # homeassistant/components/openweathermap/config_flow.py
    async def async_step_user(self, user_input=None) -> ConfigFlowResult:
        # ...
        if user_input is not None:
            # ...
            errors, description_placeholders = await validate_api_key(
                user_input[CONF_API_KEY], mode
            )

            if not errors:
                data, options = build_data_and_options(user_input)
                return self.async_create_entry(
                    title=user_input[CONF_NAME], data=data, options=options
                )
        # ...
        return self.async_show_form(
            # ...
            errors=errors,
            description_placeholders=description_placeholders,
        )
    ```
*   The `validate_api_key` function in `homeassistant/components/openweathermap/utils.py` attempts to validate the key by making a call using the `pyopenweathermap` library.
    ```python
    # homeassistant/components/openweathermap/utils.py
    async def validate_api_key(api_key, mode):
        # ...
        try:
            owm_client = create_owm_client(api_key, mode)
            api_key_valid = await owm_client.validate_key()
        except RequestError as error:
            errors["base"] = "cannot_connect"
            description_placeholders["error"] = str(error)

        if api_key_valid is False: # Assuming api_key_valid is initialized to None and set if no RequestError
            errors["base"] = "invalid_api_key"
        return errors, description_placeholders
    ```
This setup correctly handles:
*   `pyopenweathermap.RequestError` by setting `errors["base"] = "cannot_connect"`.
*   Invalid API keys (if `owm_client.validate_key()` returns `False`) by setting `errors["base"] = "invalid_api_key"`.

**Gap:**
The issue is that neither `async_step_user` in `config_flow.py` nor `validate_api_key` in `utils.py` comprehensively catches all potential exceptions that might occur during the `owm_client.validate_key()` call, as demonstrated in the rule's example implementation. The rule's example shows:
```python
            try:
                await client.get_data()
            except MyException:
                errors["base"] = "cannot_connect"
            except Exception:  # noqa: BLE001
                LOGGER.exception("Unexpected exception")
                errors["base"] = "unknown"
            # ...
```
If `owm_client.validate_key()` (or `create_owm_client`) raises an exception other than `RequestError` (e.g., a different `pyopenweathermap` specific error, or an unexpected standard Python error from within the library), this exception would propagate unhandled out of `validate_api_key`. Since the call to `validate_api_key` in `async_step_user` is not wrapped in a general `try...except Exception` block, the config flow would terminate with an unhandled exception. This leads to a poor user experience, as the user would see a generic error screen instead of a specific message within the config flow (e.g., "unknown error").

Therefore, while the integration tests the connection for common/expected issues, it does not fully adhere to the robustness suggested by the rule's example for handling unexpected failures during this test, thus not always ensuring the user is informed gracefully.

## Suggestions

To fully comply with the rule and improve the robustness of the config flow, the integration should ensure that any exception occurring during the API key validation and connection test results in a user-facing error message within the config flow.

The preferred way to achieve this, aligning with the rule's example, is to modify the `async_step_user` method in `homeassistant/components/openweathermap/config_flow.py` to include a general `try...except Exception` block around the call to `validate_api_key`.

1.  **Add a logger instance** at the beginning of `homeassistant/components/openweathermap/config_flow.py`:
    ```python
    import logging
    # ... other imports ...

    _LOGGER = logging.getLogger(__name__)
    ```

2.  **Modify `async_step_user`** to wrap the call to `validate_api_key`:
    ```python
    # In homeassistant/components/openweathermap/config_flow.py

    # ... (inside OpenWeatherMapConfigFlow class)
    async def async_step_user(self, user_input=None) -> ConfigFlowResult:
        """Handle a flow initialized by the user."""
        errors: dict[str, str] = {}
        description_placeholders: dict[str, str] = {} # Initialize for consistency

        if user_input is not None:
            latitude = user_input[CONF_LATITUDE]
            longitude = user_input[CONF_LONGITUDE]
            mode = user_input[CONF_MODE]

            await self.async_set_unique_id(f"{latitude}-{longitude}")
            self._abort_if_unique_id_configured()

            try:
                # Re-initialize errors and placeholders before the call to ensure
                # they are from the validation attempt.
                current_errors, current_placeholders = await validate_api_key(
                    user_input[CONF_API_KEY], mode
                )
                errors.update(current_errors)
                description_placeholders.update(current_placeholders)
            except Exception:  # noqa: BLE001
                _LOGGER.exception("Unexpected exception during OpenWeatherMap API key validation")
                errors["base"] = "unknown"
                # description_placeholders can be left empty or set to a generic message if desired

            if not errors:
                data, options = build_data_and_options(user_input)
                return self.async_create_entry(
                    title=user_input[CONF_NAME], data=data, options=options
                )

        schema = vol.Schema(
            # ... existing schema ...
        )

        return self.async_show_form(
            step_id="user",
            data_schema=schema,
            errors=errors,
            description_placeholders=description_placeholders,
        )
    ```

**Why these changes satisfy the rule:**
*   By wrapping the `validate_api_key` call in a `try...except Exception` block within `async_step_user`, any unexpected error during the validation process (including those not caught within `validate_api_key` itself) will be caught.
*   This ensures that instead of the config flow crashing, the user is presented with a generic "unknown" error message (or a more specific one if `description_placeholders` is populated), aligning with the user experience goals of the rule.
*   Logging the exception helps developers diagnose unexpected issues.

This change makes the config flow more resilient and improves the user experience when unforeseen problems occur during setup, which is the core intent of the `test-before-configure` rule.

_Created at 2025-05-14 15:19:07. Prompt tokens: 14025, Output tokens: 1963, Total tokens: 22558_
